<?xml version='1.0' encoding='utf-8'?>
<robot name="DPhand">
    <link name="forearm-v1">
        <inertial>
            <origin xyz="-0.000558482683742808 0.0782503410924264 4.084524217145481e-05" rpy="0.0 0.0 0.0" />
            <mass value="1.6175630960555267" />
            <inertia ixx="0.0088972914431045" iyy="0.002023124146950901" izz="0.009303332857821452" ixy="9.29484064925481e-05" iyz="-3.431499092231803e-06" ixz="-2.7537659191308348e-06" />
        </inertial>
        <visual name="forearm-v1_visual">
            <origin xyz="0.0 0.0 0.0" rpy="0.0 0.0 0.0" />
            <geometry>
                <mesh filename="meshes/forearm-v1.stl" scale="0.001 0.001 0.001" />
            </geometry>
        </visual>
        <collision name="forearm-v1_collision">
            <origin xyz="0.0 0.0 0.0" rpy="0.0 0.0 0.0" />
            <geometry>
                <mesh filename="meshes/forearm-v1.stl" scale="0.001 0.001 0.001" />
            </geometry>
        </collision>
    </link>
    <link name="wrist-v3">
        <inertial>
            <origin xyz="-3.09819185070892e-09 0.0003954460919428371 -0.020000432116471973" rpy="0.0 -0.0 0.0" />
            <mass value="0.025281790897859358" />
            <inertia ixx="3.451709867000269e-06" iyy="3.409392878076412e-06" izz="1.0849815746103754e-06" ixy="-2.3144652755451343e-12" iyz="-6.269773053349615e-11" ixz="5.64928076266329e-12" />
        </inertial>
        <visual name="wrist-v3_visual">
            <origin xyz="-6.567727429095116e-10 2.1791420223848948e-09 -0.020000001751485" rpy="-3.141592653589793 -1.5707963267948966 0" />
            <geometry>
                <mesh filename="meshes/wrist-v3.stl" scale="0.001 0.001 0.001" />
            </geometry>
        </visual>
        <collision name="wrist-v3_collision">
            <origin xyz="-6.567727429095116e-10 2.1791420223848948e-09 -0.020000001751485" rpy="-3.141592653589793 -1.5707963267948966 0" />
            <geometry>
                <mesh filename="meshes/wrist-v3.stl" scale="0.001 0.001 0.001" />
            </geometry>
        </collision>
    </link>
    <link name="palm-v7">
        <inertial>
            <origin xyz="0.0034129210462386346 -0.03865041321898858 0.013988465471689927" rpy="0.0 -8.552847072295026e-50 1.1403796096393404e-49" />
            <mass value="0.4192429775011079" />
            <inertia ixx="0.0002511183696232988" iyy="0.00013307671455294238" izz="0.0003294312488618806" ixy="5.240549461101398e-06" iyz="1.3329864627121197e-05" ixz="-2.571194510090816e-06" />
        </inertial>
        <visual name="palm-v7_visual">
            <origin xyz="-1.7514929198181664e-09 -0.004999997820858049 0.007500000656772758" rpy="-1.5707963267948972 2.1486021087536242e-12 -4.811457864580376e-12" />
            <geometry>
                <mesh filename="meshes/palm-v7.stl" scale="0.001 0.001 0.001" />
            </geometry>
        </visual>
        <collision name="palm-v7_collision">
            <origin xyz="-1.7514929198181664e-09 -0.004999997820858049 0.007500000656772758" rpy="-1.5707963267948972 2.1486021087536242e-12 -4.811457864580376e-12" />
            <geometry>
                <mesh filename="meshes/palm-v7.stl" scale="0.001 0.001 0.001" />
            </geometry>
        </collision>
    </link>
    <link name="cardan-v4">
        <inertial>
            <origin xyz="0.003008502153449424 0.008295361392211582 0.0019872835319070248" rpy="5.551115123125784e-17 -4.85722573273506e-17 0.0" />
            <mass value="0.011777208943265035" />
            <inertia ixx="3.200090882715656e-07" iyy="2.9576008342213e-07" izz="3.885663584978922e-07" ixy="-8.613590589252699e-09" iyz="-1.377230447299273e-08" ixz="-2.13050543790426e-09" />
        </inertial>
        <visual name="cardan-v4_visual">
            <origin xyz="0.03443373112442266 0.20231800920586987 0.06688757915180123" rpy="-0.8634356850573391 -0.12532783116975 1.2309594173415412" />
            <geometry>
                <mesh filename="meshes/cardan-v4.stl" scale="0.001 0.001 0.001" />
            </geometry>
        </visual>
        <collision name="cardan-v4_collision">
            <origin xyz="0.03443373112442266 0.20231800920586987 0.06688757915180123" rpy="-0.8634356850573391 -0.12532783116975 1.2309594173415412" />
            <geometry>
                <mesh filename="meshes/cardan-v4.stl" scale="0.001 0.001 0.001" />
            </geometry>
        </collision>
    </link>
    <link name="PM-v4-1">
        <inertial>
            <origin xyz="-0.002527107846388179 0.009689467144744484 0.009576421865422681" rpy="-1.1555579666323412e-33 -0.0 0.0" />
            <mass value="0.017629902331191244" />
            <inertia ixx="1.3950479375961226e-06" iyy="1.2430186138756536e-06" izz="1.3643932835624099e-06" ixy="-3.3995560469530703e-07" iyz="-4.233471265519961e-07" ixz="-2.904115955003302e-07" />
        </inertial>
        <visual name="PM-v4-1_visual">
            <origin xyz="-0.010479252670713817 -0.006214058049700952 0.005283628143143106" rpy="-2.0943951023986553 -0.36136712390656883 2.7539959669365612" />
            <geometry>
                <mesh filename="meshes/PM-v4-1.stl" scale="0.001 0.001 0.001" />
            </geometry>
        </visual>
        <collision name="PM-v4-1_collision">
            <origin xyz="-0.010479252670713817 -0.006214058049700952 0.005283628143143106" rpy="-2.0943951023986553 -0.36136712390656883 2.7539959669365612" />
            <geometry>
                <mesh filename="meshes/PM-v4-1.stl" scale="0.001 0.001 0.001" />
            </geometry>
        </collision>
    </link>
    <link name="PD-v5">
        <inertial>
            <origin xyz="-0.0010087545665515751 0.009833285579387159 0.008953184323996667" rpy="-2.672764710091145e-49 -1.3684555315672042e-48 0.0" />
            <mass value="0.03516767552150883" />
            <inertia ixx="2.2234414420196393e-06" iyy="1.9493729187417355e-06" izz="2.1800380856522673e-06" ixy="-5.867667690875787e-07" iyz="-7.094862047630243e-07" ixz="-4.921900922331195e-07" />
        </inertial>
        <visual name="PD-v5_visual">
            <origin xyz="-0.009441135032779959 -0.0017581571288167552 -0.00015459252803576184" rpy="-2.0943951023989476 -0.36136712390611336 2.753995966937124" />
            <geometry>
                <mesh filename="meshes/PD-v5.stl" scale="0.001 0.001 0.001" />
            </geometry>
        </visual>
        <collision name="PD-v5_collision">
            <origin xyz="-0.009441135032779959 -0.0017581571288167552 -0.00015459252803576184" rpy="-2.0943951023989476 -0.36136712390611336 2.753995966937124" />
            <geometry>
                <mesh filename="meshes/PD-v5.stl" scale="0.001 0.001 0.001" />
            </geometry>
        </collision>
    </link>
    <link name="PP-v4-2">
        <inertial>
            <origin xyz="-0.013234142733120598 0.01613589246371719 -0.006170072319999136" rpy="0.0 -0.0 0.0" />
            <mass value="0.03244469741401904" />
            <inertia ixx="3.6953849465374937e-06" iyy="3.1481398423543595e-06" izz="4.569527029404067e-06" ixy="1.3680960071333095e-06" iyz="6.711870825073153e-07" ixz="-5.114948862133629e-07" />
        </inertial>
        <visual name="PP-v4-2_visual">
            <origin xyz="-0.054313136501666234 -0.16066064691450577 -0.11999879475611558" rpy="-0.9513682007635534 0.831880129207292 -2.123463692819812" />
            <geometry>
                <mesh filename="meshes/PP-v4-2.stl" scale="0.001 0.001 0.001" />
            </geometry>
        </visual>
        <collision name="PP-v4-2_collision">
            <origin xyz="-0.054313136501666234 -0.16066064691450577 -0.11999879475611558" rpy="-0.9513682007635534 0.831880129207292 -2.123463692819812" />
            <geometry>
                <mesh filename="meshes/PP-v4-2.stl" scale="0.001 0.001 0.001" />
            </geometry>
        </collision>
    </link>
    <link name="PM-v4">
        <inertial>
            <origin xyz="-0.0019123068521168475 0.012336023477299634 -0.006012124809526513" rpy="0.0 -0.0 0.0" />
            <mass value="0.017629902331191244" />
            <inertia ixx="1.7136309629533011e-06" iyy="7.044905772674437e-07" izz="1.5843382948125227e-06" ixy="1.3505127012106074e-07" iyz="-2.5399096607433484e-07" ixz="3.619153237446856e-08" />
        </inertial>
        <visual name="PM-v4_visual">
            <origin xyz="-0.0068857164734172005 -0.004730695999156041 -0.01032247072490005" rpy="3.141592653582047 1.308996938995763 1.5707963267874119" />
            <geometry>
                <mesh filename="meshes/PM-v4.stl" scale="0.001 0.001 0.001" />
            </geometry>
        </visual>
        <collision name="PM-v4_collision">
            <origin xyz="-0.0068857164734172005 -0.004730695999156041 -0.01032247072490005" rpy="3.141592653582047 1.308996938995763 1.5707963267874119" />
            <geometry>
                <mesh filename="meshes/PM-v4.stl" scale="0.001 0.001 0.001" />
            </geometry>
        </collision>
    </link>
    <link name="PD-v5-2">
        <inertial>
            <origin xyz="-0.0014676840782965267 0.012492452398043809 -0.0044334000246859075" rpy="-2.5658540753360864e-49 -0.0 0.0" />
            <mass value="0.03516767552150883" />
            <inertia ixx="2.7571506296900777e-06" iyy="1.0477837348280586e-06" izz="2.547918081896313e-06" ixy="2.1410057890332802e-07" iyz="-4.393624237236708e-07" ixz="5.8193585754686684e-08" />
        </inertial>
        <visual name="PD-v5-2_visual">
            <origin xyz="-6.568537158635479e-10 -0.0038544124328493013 -0.00879735455538539" rpy="3.1415926535809473 1.3089969389958849 1.5707963267893772" />
            <geometry>
                <mesh filename="meshes/PD-v5-2.stl" scale="0.001 0.001 0.001" />
            </geometry>
        </visual>
        <collision name="PD-v5-2_collision">
            <origin xyz="-6.568537158635479e-10 -0.0038544124328493013 -0.00879735455538539" rpy="3.1415926535809473 1.3089969389958849 1.5707963267893772" />
            <geometry>
                <mesh filename="meshes/PD-v5-2.stl" scale="0.001 0.001 0.001" />
            </geometry>
        </collision>
    </link>
    <link name="PP-v4-3">
        <inertial>
            <origin xyz="-0.0055461940404727605 0.006875837726140013 -0.01988823693277855" rpy="-5.551115123125783e-17 -9.183549615799121e-41 1.8367099231598242e-40" />
            <mass value="0.03244469741401904" />
            <inertia ixx="4.6523160923493e-06" iyy="4.479612459207185e-06" izz="2.2811232667320147e-06" ixy="2.510203439638711e-07" iyz="8.848488297830328e-07" ixz="-7.100738530453325e-07" />
        </inertial>
        <visual name="PP-v4-3_visual">
            <origin xyz="0.20742845303951188 -0.010682657642734572 -0.0045592755156704" rpy="0.5387391192333411 0.22606446325080357 0.13318154107303318" />
            <geometry>
                <mesh filename="meshes/PP-v4-3.stl" scale="0.001 0.001 0.001" />
            </geometry>
        </visual>
        <collision name="PP-v4-3_collision">
            <origin xyz="0.20742845303951188 -0.010682657642734572 -0.0045592755156704" rpy="0.5387391192333411 0.22606446325080357 0.13318154107303318" />
            <geometry>
                <mesh filename="meshes/PP-v4-3.stl" scale="0.001 0.001 0.001" />
            </geometry>
        </collision>
    </link>
    <link name="cardan-v4-1">
        <inertial>
            <origin xyz="-0.0016023537935569887 0.0018372179371438336 0.008710361625333854" rpy="0.0 -0.0 0.0" />
            <mass value="0.011777208943265035" />
            <inertia ixx="3.5543098153582273e-07" iyy="3.4597845556560883e-07" izz="3.029260930876877e-07" ixy="-2.7610675372606892e-08" iyz="-2.0683194380624244e-08" ixz="2.4735572941128183e-08" />
        </inertial>
        <visual name="cardan-v4-1_visual">
            <origin xyz="-0.047608836444580666 0.0026268595980586795 0.21052007713025916" rpy="-0.8027288082206521 -1.202696244060722 2.3388638453774453" />
            <geometry>
                <mesh filename="meshes/cardan-v4-1.stl" scale="0.001 0.001 0.001" />
            </geometry>
        </visual>
        <collision name="cardan-v4-1_collision">
            <origin xyz="-0.047608836444580666 0.0026268595980586795 0.21052007713025916" rpy="-0.8027288082206521 -1.202696244060722 2.3388638453774453" />
            <geometry>
                <mesh filename="meshes/cardan-v4-1.stl" scale="0.001 0.001 0.001" />
            </geometry>
        </collision>
    </link>
    <link name="cardan-v4-2">
        <inertial>
            <origin xyz="-0.0007066525662759215 0.0005103163686035472 0.009002975353394251" rpy="-1.6673541341794503e-72 -0.0 0.0" />
            <mass value="0.011777208943265035" />
            <inertia ixx="3.6428160739266323e-07" iyy="3.489177461107662e-07" izz="2.9113617669028653e-07" ixy="-3.3078920149649045e-08" iyz="-1.8626813479641535e-09" ixz="2.754270426669412e-10" />
        </inertial>
        <visual name="cardan-v4-2_visual">
            <origin xyz="-0.008500000656343102 0.053281859938311485 0.20899999824840623" rpy="-1.5707963267948966 -1.5707963267896272 0" />
            <geometry>
                <mesh filename="meshes/cardan-v4-2.stl" scale="0.001 0.001 0.001" />
            </geometry>
        </visual>
        <collision name="cardan-v4-2_collision">
            <origin xyz="-0.008500000656343102 0.053281859938311485 0.20899999824840623" rpy="-1.5707963267948966 -1.5707963267896272 0" />
            <geometry>
                <mesh filename="meshes/cardan-v4-2.stl" scale="0.001 0.001 0.001" />
            </geometry>
        </collision>
    </link>
    <link name="PP-v4-4">
        <inertial>
            <origin xyz="-9.584503790332939e-06 0.007241550618303716 -0.020521670242879254" rpy="0.0 -0.0 0.0" />
            <mass value="0.03244469741401904" />
            <inertia ixx="4.849187616658233e-06" iyy="4.446210951678046e-06" izz="2.1176532499657304e-06" ixy="-3.790362711351673e-09" iyz="9.609651129251934e-07" ixz="4.413790417806946e-09" />
        </inertial>
        <visual name="PP-v4-4_visual">
            <origin xyz="0.19999999824826095 -0.03750214741166493 0.04189344339591319" rpy="0.5235987755983006 3.0923927783749853e-12 3.937871360953313e-13" />
            <geometry>
                <mesh filename="meshes/PP-v4-4.stl" scale="0.001 0.001 0.001" />
            </geometry>
        </visual>
        <collision name="PP-v4-4_collision">
            <origin xyz="0.19999999824826095 -0.03750214741166493 0.04189344339591319" rpy="0.5235987755983006 3.0923927783749853e-12 3.937871360953313e-13" />
            <geometry>
                <mesh filename="meshes/PP-v4-4.stl" scale="0.001 0.001 0.001" />
            </geometry>
        </collision>
    </link>
    <link name="PD-v5-1">
        <inertial>
            <origin xyz="-0.0014676840781601263 0.01091933078169454 -0.007515621808224609" rpy="5.560974942591235e-73 -0.0 0.0" />
            <mass value="0.03516767552150883" />
            <inertia ixx="2.7571506296892104e-06" iyy="9.285924696742598e-07" izz="2.66710934705011e-06" ixy="2.2186688687903628e-07" iyz="-5.465433650521922e-09" ixz="7.973800174191026e-10" />
        </inertial>
        <visual name="PD-v5-1_visual">
            <origin xyz="-6.567489518882752e-10 -0.006000002681831234 -0.007499998248271283" rpy="1.570796326796466 1.5707963267924463 0" />
            <geometry>
                <mesh filename="meshes/PD-v5-1.stl" scale="0.001 0.001 0.001" />
            </geometry>
        </visual>
        <collision name="PD-v5-1_collision">
            <origin xyz="-6.567489518882752e-10 -0.006000002681831234 -0.007499998248271283" rpy="1.570796326796466 1.5707963267924463 0" />
            <geometry>
                <mesh filename="meshes/PD-v5-1.stl" scale="0.001 0.001 0.001" />
            </geometry>
        </collision>
    </link>
    <link name="PM-v4-2">
        <inertial>
            <origin xyz="-0.0019123068520370784 0.010359629805805 -0.00900006141707459" rpy="0.0 -0.0 0.0" />
            <mass value="0.017629902331191244" />
            <inertia ixx="1.7136309629546022e-06" iyy="6.364337155743541e-07" izz="1.652395156505164e-06" ixy="1.3981656753078936e-07" iyz="-6.995692780799351e-13" ixz="4.495041184463872e-12" />
        </inertial>
        <visual name="PM-v4-2_visual">
            <origin xyz="-0.0068857164733736875 -0.00724115492040319 -0.008746343819090494" rpy="1.570796326796466 1.5707963267917586 0" />
            <geometry>
                <mesh filename="meshes/PM-v4-2.stl" scale="0.001 0.001 0.001" />
            </geometry>
        </visual>
        <collision name="PM-v4-2_collision">
            <origin xyz="-0.0068857164733736875 -0.00724115492040319 -0.008746343819090494" rpy="1.570796326796466 1.5707963267917586 0" />
            <geometry>
                <mesh filename="meshes/PM-v4-2.stl" scale="0.001 0.001 0.001" />
            </geometry>
        </collision>
    </link>
    <link name="PM-v4-3">
        <inertial>
            <origin xyz="-0.0019123068519958295 0.0076772507789257816 -0.011374663719495333" rpy="0.0 -0.0 0.0" />
            <mass value="0.017629902331191244" />
            <inertia ixx="1.7136309629546022e-06" iyy="7.044898777017128e-07" izz="1.5843389943787957e-06" ixy="1.3505359692443612e-07" iyz="2.539897543914812e-07" ixz="-3.618284862235133e-08" />
        </inertial>
        <visual name="PM-v4-3_visual">
            <origin xyz="-0.006885716473311665 -0.009258134804623097 -0.006574173043055853" rpy="-1.1638440828875818e-16 1.3089969389948493 -1.5707963267952947" />
            <geometry>
                <mesh filename="meshes/PM-v4-3.stl" scale="0.001 0.001 0.001" />
            </geometry>
        </visual>
        <collision name="PM-v4-3_collision">
            <origin xyz="-0.006885716473311665 -0.009258134804623097 -0.006574173043055853" rpy="-1.1638440828875818e-16 1.3089969389948493 -1.5707963267952947" />
            <geometry>
                <mesh filename="meshes/PM-v4-3.stl" scale="0.001 0.001 0.001" />
            </geometry>
        </collision>
    </link>
    <link name="PD-v5-3">
        <inertial>
            <origin xyz="-0.001467684078155655 0.00860207504845505 -0.010085668871892" rpy="2.4651903288156624e-32 6.162975822039156e-33 0.0" />
            <mass value="0.03516767552150883" />
            <inertia ixx="2.7571506296892095e-06" iyy="1.0423183011832157e-06" izz="2.5533835155420905e-06" ixy="2.1451333317197156e-07" iyz="4.2989601496585303e-07" ixz="-5.6653165851235595e-08" />
        </inertial>
        <visual name="PD-v5-3_visual">
            <origin xyz="-6.567208898911048e-10 -0.007736702432673824 -0.005691531940968302" rpy="-5.989612986033893e-16 1.3089969389940166 -1.5707963267983984" />
            <geometry>
                <mesh filename="meshes/PD-v5-3.stl" scale="0.001 0.001 0.001" />
            </geometry>
        </visual>
        <collision name="PD-v5-3_collision">
            <origin xyz="-6.567208898911048e-10 -0.007736702432673824 -0.005691531940968302" rpy="-5.989612986033893e-16 1.3089969389940166 -1.5707963267983984" />
            <geometry>
                <mesh filename="meshes/PD-v5-3.stl" scale="0.001 0.001 0.001" />
            </geometry>
        </collision>
    </link>
    <link name="PP-v4">
        <inertial>
            <origin xyz="0.005527678081821552 0.00687831792500841 -0.019892532763011773" rpy="0.0 9.183549615799121e-41 -1.8367099231598242e-40" />
            <mass value="0.03244469741401904" />
            <inertia ixx="4.6465984563522615e-06" iyy="4.48152407123835e-06" izz="2.284929290711848e-06" ixy="-2.577715681849761e-07" iyz="8.820946207227223e-07" ixz="7.176113039134182e-07" />
        </inertial>
        <visual name="PP-v4_visual">
            <origin xyz="0.17894187397235164 -0.062446466663464886 0.08509827170096383" rpy="0.5387391192340548 -0.2260644632529056 -0.13318154107125135" />
            <geometry>
                <mesh filename="meshes/PP-v4.stl" scale="0.001 0.001 0.001" />
            </geometry>
        </visual>
        <collision name="PP-v4_collision">
            <origin xyz="0.17894187397235164 -0.062446466663464886 0.08509827170096383" rpy="0.5387391192340548 -0.2260644632529056 -0.13318154107125135" />
            <geometry>
                <mesh filename="meshes/PP-v4.stl" scale="0.001 0.001 0.001" />
            </geometry>
        </collision>
    </link>
    <link name="cardan-v4-3">
        <inertial>
            <origin xyz="-0.0028991325908934115 0.002823063125748355 0.008089414271337103" rpy="0.0 -0.0 0.0" />
            <mass value="0.011777208943265035" />
            <inertia ixx="3.552897154340386e-07" iyy="3.441157742186112e-07" izz="3.0493004053999653e-07" ixy="-2.6637944646429e-08" iyz="-2.376262078703627e-08" ixz="2.473070102802644e-08" />
        </inertial>
        <visual name="cardan-v4-3_visual">
            <origin xyz="-0.05689116138730593 0.10555949844276147 0.17947922416927456" rpy="2.3388638453777304 -1.2026962440637075 2.3388638453694304" />
            <geometry>
                <mesh filename="meshes/cardan-v4-3.stl" scale="0.001 0.001 0.001" />
            </geometry>
        </visual>
        <collision name="cardan-v4-3_collision">
            <origin xyz="-0.05689116138730593 0.10555949844276147 0.17947922416927456" rpy="2.3388638453777304 -1.2026962440637075 2.3388638453694304" />
            <geometry>
                <mesh filename="meshes/cardan-v4-3.stl" scale="0.001 0.001 0.001" />
            </geometry>
        </collision>
    </link>
    <link name="cardan-v4-4">
        <inertial>
            <origin xyz="-0.004640982509914131 0.005581922249033369 0.005395998768704442" rpy="0.0 -0.0 0.0" />
            <mass value="0.011777208943265035" />
            <inertia ixx="3.29006226085068e-07" iyy="3.2815784380911653e-07" izz="3.471714602983527e-07" ixy="-6.129753921633833e-09" iyz="-3.8211970989100253e-08" ixz="3.117955973818096e-08" />
        </inertial>
        <visual name="cardan-v4-4_visual">
            <origin xyz="-0.0876314764894241 0.16352341971737527 0.11033141956904868" rpy="2.257106736457741 -0.7355702447352509 2.2571067364623834" />
            <geometry>
                <mesh filename="meshes/cardan-v4-4.stl" scale="0.001 0.001 0.001" />
            </geometry>
        </visual>
        <collision name="cardan-v4-4_collision">
            <origin xyz="-0.0876314764894241 0.16352341971737527 0.11033141956904868" rpy="2.257106736457741 -0.7355702447352509 2.2571067364623834" />
            <geometry>
                <mesh filename="meshes/cardan-v4-4.stl" scale="0.001 0.001 0.001" />
            </geometry>
        </collision>
    </link>
    <link name="PP-v4-1">
        <inertial>
            <origin xyz="0.012262704283518588 0.005309852038908111 -0.017175870158242325" rpy="0.0 -0.0 0.0" />
            <mass value="0.03244469741401904" />
            <inertia ixx="3.8628934446861656e-06" iyy="4.6106533801540935e-06" izz="2.9395049934563655e-06" ixy="-4.4001004928491097e-07" iyz="5.813056297322842e-07" ixz="1.3658391427977926e-06" />
        </inertial>
        <visual name="PP-v4-1_visual">
            <origin xyz="0.13226542788627707 -0.0898835923004781 0.13262076731841918" rpy="0.6139498942867604 -0.519829036167037 -0.3367672610274475" />
            <geometry>
                <mesh filename="meshes/PP-v4-1.stl" scale="0.001 0.001 0.001" />
            </geometry>
        </visual>
        <collision name="PP-v4-1_collision">
            <origin xyz="0.13226542788627707 -0.0898835923004781 0.13262076731841918" rpy="0.6139498942867604 -0.519829036167037 -0.3367672610274475" />
            <geometry>
                <mesh filename="meshes/PP-v4-1.stl" scale="0.001 0.001 0.001" />
            </geometry>
        </collision>
    </link>
    <link name="PD-v5-4">
        <inertial>
            <origin xyz="-0.0014676840780382138 0.004633807076127709 -0.012419513294821619" rpy="1.1209361811213426e-44 -0.0 0.0" />
            <mass value="0.03516767552150883" />
            <inertia ixx="2.7571506296892104e-06" iyy="1.4954111849022193e-06" izz="2.100290631821443e-06" ixy="1.8220007233796196e-07" iyz="8.149664519894888e-07" ixz="-1.2660444284941097e-07" />
        </inertial>
        <visual name="PD-v5-4_visual">
            <origin xyz="-6.566129173712909e-10 -0.009216738212699341 -0.002702184230323388" rpy="3.6818748826087445e-12 0.9599310886008128 -1.570796326793067" />
            <geometry>
                <mesh filename="meshes/PD-v5-4.stl" scale="0.001 0.001 0.001" />
            </geometry>
        </visual>
        <collision name="PD-v5-4_collision">
            <origin xyz="-6.566129173712909e-10 -0.009216738212699341 -0.002702184230323388" rpy="3.6818748826087445e-12 0.9599310886008128 -1.570796326793067" />
            <geometry>
                <mesh filename="meshes/PD-v5-4.stl" scale="0.001 0.001 0.001" />
            </geometry>
        </collision>
    </link>
    <link name="PM-v4-4">
        <inertial>
            <origin xyz="-0.0019123068518981001 0.003323887632898348 -0.013314463918496848" rpy="0.0 -0.0 0.0" />
            <mass value="0.017629902331191244" />
            <inertia ixx="1.7136309629543853e-06" iyy="9.706741398381766e-07" izz="1.318154732241712e-06" ixy="1.1453360536850521e-07" iyz="4.773454952555355e-07" ixz="-8.019180642489481e-08" />
        </inertial>
        <visual name="PM-v4-4_visual">
            <origin xyz="-0.006885716473229234 -0.010948304720997904 -0.0030112352492257612" rpy="3.747103313428587e-12 0.959931088601694 -1.5707963267918277" />
            <geometry>
                <mesh filename="meshes/PM-v4-4.stl" scale="0.001 0.001 0.001" />
            </geometry>
        </visual>
        <collision name="PM-v4-4_collision">
            <origin xyz="-0.006885716473229234 -0.010948304720997904 -0.0030112352492257612" rpy="3.747103313428587e-12 0.959931088601694 -1.5707963267918277" />
            <geometry>
                <mesh filename="meshes/PM-v4-4.stl" scale="0.001 0.001 0.001" />
            </geometry>
        </collision>
    </link>
    <link name="point-v1">
        <inertial>
            <origin xyz="1.1768423389783845e-09 -3.175773244379343e-09 -6.566897725601706e-10" rpy="2.2420775429197073e-44 -0.0 0.0" />
            <mass value="4.110250388446646e-06" />
            <inertia ixx="4.110250388319086e-13" iyy="4.110250388446782e-13" izz="4.110250388319087e-13" ixy="-4.07831529250063e-56" iyz="8.30058455555689e-41" ixz="-2.0194839173689874e-28" />
        </inertial>
        <visual name="point-v1_visual">
            <origin xyz="1.1768423389783845e-09 -3.175773244379343e-09 -6.566897725601706e-10" rpy="-1.5707963267933271 -3.765258830442259e-16 2.3049321375055693e-12" />
            <geometry>
                <mesh filename="meshes/point-v1.stl" scale="0.001 0.001 0.001" />
            </geometry>
        </visual>
        <collision name="point-v1_collision">
            <origin xyz="1.1768423389783845e-09 -3.175773244379343e-09 -6.566897725601706e-10" rpy="-1.5707963267933271 -3.765258830442259e-16 2.3049321375055693e-12" />
            <geometry>
                <mesh filename="meshes/point-v1.stl" scale="0.001 0.001 0.001" />
            </geometry>
        </collision>
    </link>
    <link name="point-v1-4">
        <inertial>
            <origin xyz="-2.5490058863653078e-09 3.279874789541282e-09 3.5850566248996073e-09" rpy="0.0 -0.0 0.0" />
            <mass value="4.110250388446646e-06" />
            <inertia ixx="4.110250388319085e-13" iyy="4.1102503885176093e-13" izz="4.1102503877896903e-13" ixy="-5.704118273296692e-30" iyz="1.3234915469380665e-23" ixz="-3.3087452666852004e-24" />
        </inertial>
        <visual name="point-v1-4_visual">
            <origin xyz="-2.5490058863653078e-09 3.279874754014145e-09 3.5850566248996073e-09" rpy="-1.0550353695586359 0.09463229801255459 0.620249485987349" />
            <geometry>
                <mesh filename="meshes/point-v1-4.stl" scale="0.001 0.001 0.001" />
            </geometry>
        </visual>
        <collision name="point-v1-4_collision">
            <origin xyz="-2.5490058863653078e-09 3.279874754014145e-09 3.5850566248996073e-09" rpy="-1.0550353695586359 0.09463229801255459 0.620249485987349" />
            <geometry>
                <mesh filename="meshes/point-v1-4.stl" scale="0.001 0.001 0.001" />
            </geometry>
        </collision>
    </link>
    <link name="point-v1-2">
        <inertial>
            <origin xyz="2.2349162875912043e-09 2.2510938180175798e-09 -6.565698507099426e-10" rpy="0.0 -0.0 1.7722582357313383e-75" />
            <mass value="4.110250388446646e-06" />
            <inertia ixx="4.110250388319087e-13" iyy="4.1102503883852614e-13" izz="4.1102503872602957e-13" ixy="2.6469779601696886e-23" iyz="-3.308722450212111e-24" ixz="-1.7219740117411693e-36" />
        </inertial>
        <visual name="point-v1-2_visual">
            <origin xyz="2.2349162875912043e-09 2.2510938180175798e-09 -6.565698507099426e-10" rpy="-1.5707963267936864 -1.7307266730898733e-12 -0.6108652381940859" />
            <geometry>
                <mesh filename="meshes/point-v1-2.stl" scale="0.001 0.001 0.001" />
            </geometry>
        </visual>
        <collision name="point-v1-2_collision">
            <origin xyz="2.2349162875912043e-09 2.2510938180175798e-09 -6.565698507099426e-10" rpy="-1.5707963267936864 -1.7307266730898733e-12 -0.6108652381940859" />
            <geometry>
                <mesh filename="meshes/point-v1-2.stl" scale="0.001 0.001 0.001" />
            </geometry>
        </collision>
    </link>
    <link name="point-v1-3">
        <inertial>
            <origin xyz="-3.3026763013310755e-09 -4.894265401844677e-09 -6.568638555304318e-10" rpy="0.0 -0.0 0.0" />
            <mass value="4.110250388446646e-06" />
            <inertia ixx="4.1102503872602957e-13" iyy="4.110250388451436e-13" izz="4.1102503872602957e-13" ixy="-1.3234889800848443e-23" iyz="1.654361225106055e-24" ixz="2.0680656137574905e-25" />
        </inertial>
        <visual name="point-v1-3_visual">
            <origin xyz="-3.3026763013310755e-09 -4.894265401844677e-09 -6.568638555304318e-10" rpy="1.570796326794379 -2.2317425685247577e-12 0.26179938779901263" />
            <geometry>
                <mesh filename="meshes/point-v1-3.stl" scale="0.001 0.001 0.001" />
            </geometry>
        </visual>
        <collision name="point-v1-3_collision">
            <origin xyz="-3.3026763013310755e-09 -4.894265401844677e-09 -6.568638555304318e-10" rpy="1.570796326794379 -2.2317425685247577e-12 0.26179938779901263" />
            <geometry>
                <mesh filename="meshes/point-v1-3.stl" scale="0.001 0.001 0.001" />
            </geometry>
        </collision>
    </link>
    <link name="point-v1-1">
        <inertial>
            <origin xyz="1.8860564043876593e-09 -9.807413903217822e-10 -6.567029886550557e-10" rpy="0.0 -0.0 2.8099773850318106e-71" />
            <mass value="4.110250388446646e-06" />
            <inertia ixx="4.1102503872602957e-13" iyy="4.110250388434892e-13" izz="4.1102503872602957e-13" ixy="-1.0375730693255897e-41" iyz="-2.0751461383546696e-41" ixz="-2.2816473051316246e-29" />
        </inertial>
        <visual name="point-v1-1_visual">
            <origin xyz="1.8860564043876593e-09 -9.807413903217822e-10 -6.567029886550557e-10" rpy="-1.570796326794506 1.0308420783648451e-13 -0.2617993878008802" />
            <geometry>
                <mesh filename="meshes/point-v1-1.stl" scale="0.001 0.001 0.001" />
            </geometry>
        </visual>
        <collision name="point-v1-1_collision">
            <origin xyz="1.8860564043876593e-09 -9.807413903217822e-10 -6.567029886550557e-10" rpy="-1.570796326794506 1.0308420783648451e-13 -0.2617993878008802" />
            <geometry>
                <mesh filename="meshes/point-v1-1.stl" scale="0.001 0.001 0.001" />
            </geometry>
        </collision>
    </link>
    <joint name="forearm-v1_fbwrist" type="revolute">
        <origin xyz="0.02003896 0.20200076 -0.00012216" rpy="-3.141592653589793 -1.5707963267948966 0" />
        <parent link="forearm-v1" />
        <child link="wrist-v3" />
        <axis xyz="0.0 0.0 1.0" />
        <limit lower="-1.396263" upper="1.396263" effort="1000000" velocity="1000000" />
    </joint>
    <joint name="wrist-v3_lrwrist" type="revolute">
        <origin xyz="0.00745 -0.01 -0.02" rpy="1.48029736616688e-16 -1.5707963267948966 0" />
        <parent link="wrist-v3" />
        <child link="palm-v7" />
        <axis xyz="7.703719777548943e-34 1.48029736616688e-16 1.0" />
        <limit lower="-0.349066" upper="0.349066" effort="1000000" velocity="1000000" />
    </joint>
    <joint name="palm-v7_MCP01" type="revolute">
        <origin xyz="-0.010902589999999998 -0.01590258000000002 -0.01179423" rpy="1.2060064195069047 0.134031561411219 -2.804982774554807" />
        <parent link="palm-v7" />
        <child link="cardan-v4" />
        <axis xyz="0.330718474622827 0.9354138252313552 0.12500005740876408" />
        <limit lower="-0.523599" upper="1.570796" effort="1000000" velocity="1000000" />
    </joint>
    <joint name="cardan-v4_MCP02" type="revolute">
        <origin xyz="0.002516867418881397 0.009037451714919733 -0.0022890853655482247" rpy="-0.9111954622534815 0.36136712390670794 3.141592653589793" />
        <parent link="cardan-v4" />
        <child link="PP-v4-2" />
        <axis xyz="-0.46770700000000004 -0.5760358156595738 0.6703972997017587" />
        <limit lower="-0.610865" upper="0.610865" effort="1000000" velocity="1000000" />
    </joint>
    <joint name="PP-v4-2_PIP0" type="revolute">
        <origin xyz="-0.021115499999999995 0.03996860086736463 -0.008719547409716881" rpy="-1.5707963267948966 -0.5235987755983007 1.5707963267948966" />
        <parent link="PP-v4-2" />
        <child link="PM-v4-1" />
        <axis xyz="0.8660250000000003 -0.353553 -0.353553" />
        <limit lower="-1.919862" upper="0.0" effort="1000000" velocity="1000000" />
    </joint>
    <joint name="PM-v4-1_DIP0" type="revolute">
        <origin xyz="0.013019559999999998 0.02088384999999999 0.015250049999999998" rpy="-1.665334536936862e-16 -5.551115123125783e-17 4.857225732735061e-17" />
        <parent link="PM-v4-1" />
        <child link="PD-v5" />
        <axis xyz="0.866025 -0.3535529999999999 -0.35355300000072015" />
        <limit lower="-1.22173" upper="0.0" effort="1000000" velocity="1000000" />
    </joint>
    <joint name="palm-v7_旋转-10" type="revolute">
        <origin xyz="-0.02825952 -0.07569264 0.007500000000000011" rpy="1.4860317977762118e-15 -1.3089969389957468 3.141592653589792" />
        <parent link="palm-v7" />
        <child link="cardan-v4-1" />
        <axis xyz="-0.2500000449596978 0.258819 0.9330128696840945" />
        <limit lower="-0.523599" upper="1.570796" effort="1000000" velocity="1000000" />
    </joint>
    <joint name="cardan-v4-1_旋转-11" type="revolute">
        <origin xyz="-0.005060580572069349 0.004019739999999992 0.007175111359532633" rpy="-2.0943951023931975 -1.3089969389957468 -3.141592653589793" />
        <parent link="cardan-v4-1" />
        <child link="PP-v4-3" />
        <axis xyz="0.12941000000000003 -0.9914811503124188 -0.014754272912058275" />
        <limit lower="-0.610865" upper="0.610865" effort="1000000" velocity="1000000" />
    </joint>
    <joint name="PP-v4-3_旋转-12" type="revolute">
        <origin xyz="-0.02033194999999999 0.01706223365505867 -0.03761483558117305" rpy="-1.5707963267948966 -0.5235987755983008 1.5707963267948966" />
        <parent link="PP-v4-3" />
        <child link="PM-v4" />
        <axis xyz="-1.102042353627449e-24 -0.258819 0.965926" />
        <limit lower="-1.919862" upper="0.0" effort="1000000" velocity="1000000" />
    </joint>
    <joint name="PM-v4_旋转-13" type="revolute">
        <origin xyz="-0.0015000000000000002 0.02827838 0.006024250000000002" rpy="-1.665334536932823e-16 5.551115109299817e-17 -2.0194839173657902e-28" />
        <parent link="PM-v4" />
        <child link="PD-v5-2" />
        <axis xyz="-5.3619665232645436e-17 -0.2588190000000002 0.965926" />
        <limit lower="-1.22173" upper="0.0" effort="1000000" velocity="1000000" />
    </joint>
    <joint name="palm-v7_旋转-14" type="revolute">
        <origin xyz="-0.009000000000000001 -0.08326476 0.007500000000000013" rpy="-2.1333700009901106e-17 1.5707963267948966 0" />
        <parent link="palm-v7" />
        <child link="cardan-v4-2" />
        <axis xyz="2.457291640230475e-28 -2.13337000099011e-17 1.0" />
        <limit lower="-0.523599" upper="1.570796" effort="1000000" velocity="1000000" />
    </joint>
    <joint name="cardan-v4-2_旋转-15" type="revolute">
        <origin xyz="0.00303109 -0.0017500000000000072 0.009000000000000001" rpy="-2.0943951023931975 -1.5707963267948966 0" />
        <parent link="cardan-v4-2" />
        <child link="PP-v4-4" />
        <axis xyz="1.7215661062533988e-29 -0.9999996503124186 2.018922172775106e-07" />
        <limit lower="-0.610865" upper="0.610865" effort="1000000" velocity="1000000" />
    </joint>
    <joint name="PP-v4-4_旋转-16" type="revolute">
        <origin xyz="-0.009000000000000001 0.018993043655058665 -0.040959096600935115" rpy="-1.5707963267948966 -0.5235987755983009 1.5707963267948966" />
        <parent link="PP-v4-4" />
        <child link="PM-v4-2" />
        <axis xyz="-2.676009012988934e-28 0.0 1.0" />
        <limit lower="-1.919862" upper="0.0" effort="1000000" velocity="1000000" />
    </joint>
    <joint name="PM-v4-2_旋转-17" type="revolute">
        <origin xyz="-0.0015000000000000002 0.02887400999999997 -0.0015000000000000002" rpy="-1.665334536936862e-16 -2.0296447332368827e-28 -2.465190328815662e-32" />
        <parent link="PM-v4-2" />
        <child link="PD-v5-1" />
        <axis xyz="-6.463642797520512e-29 -1.665334536936862e-16 1.0" />
        <limit lower="-1.22173" upper="0.0" effort="1000000" velocity="1000000" />
    </joint>
    <joint name="palm-v7_旋转-18" type="revolute">
        <origin xyz="0.010872860000000002 -0.08035138 0.007500000000000013" rpy="3.141592653589793 1.3089969389957468 3.141592653589793" />
        <parent link="palm-v7" />
        <child link="cardan-v4-3" />
        <axis xyz="-0.2500000449596977 0.258819 0.9330128696840945" />
        <limit lower="-0.523599" upper="1.570796" effort="1000000" velocity="1000000" />
    </joint>
    <joint name="cardan-v4-3_旋转-19" type="revolute">
        <origin xyz="0.0005605818333471468 0.000639000000000003 0.009619112567374452" rpy="1.0471975511965954 -1.3089969389957468 -3.141592653589793" />
        <parent link="cardan-v4-3" />
        <child link="PP-v4" />
        <axis xyz="-0.12941000000000003 -0.9914811503124188 -0.014754272912058164" />
        <limit lower="-0.610865" upper="0.610865" effort="1000000" velocity="1000000" />
    </joint>
    <joint name="PP-v4_旋转-20" type="revolute">
        <origin xyz="0.0029452800000000015 0.01939160365505865 -0.041649422770799735" rpy="-1.5707963267948966 -0.5235987755983008 1.5707963267948966" />
        <parent link="PP-v4" />
        <child link="PM-v4-3" />
        <axis xyz="5.361966454337766e-17 0.258819 0.965926" />
        <limit lower="-1.919862" upper="0.0" effort="1000000" velocity="1000000" />
    </joint>
    <joint name="PM-v4-3_旋转-21" type="revolute">
        <origin xyz="-0.0015000000000000005 0.027501930000000032 -0.00892203" rpy="-1.6653345369367357e-16 3.2973251850687043e-25 5.048709793414476e-29" />
        <parent link="PM-v4-3" />
        <child link="PD-v5-3" />
        <axis xyz="5.36196642248935e-17 0.2588189999999998 0.9659259999999998" />
        <limit lower="-1.22173" upper="0.0" effort="1000000" velocity="1000000" />
    </joint>
    <joint name="palm-v7_旋转-22" type="revolute">
        <origin xyz="0.029400040000000002 -0.06267863000000003 0.00750000000000001" rpy="-3.141592653589793 0.9599310885968814 -3.141592653589793" />
        <parent link="palm-v7" />
        <child link="cardan-v4-4" />
        <axis xyz="-0.469846284989832 0.573576 0.6710100353834163" />
        <limit lower="-0.523599" upper="1.570796" effort="1000000" velocity="1000000" />
    </joint>
    <joint name="cardan-v4-4_旋转-23" type="revolute">
        <origin xyz="-0.002321427225889161 0.0037286700000000294 0.008599885813189646" rpy="1.0471975511965956 -0.9599310885968814 3.141592653589793" />
        <parent link="cardan-v4-4" />
        <child link="PP-v4-1" />
        <axis xyz="-0.28678800000000004 -0.9547876503124184 -0.07830927921958675" />
        <limit lower="-0.610865" upper="0.610865" effort="1000000" velocity="1000000" />
    </joint>
    <joint name="PP-v4-1_旋转-24" type="revolute">
        <origin xyz="0.01842029 0.017507938655058678 -0.0383868192863606" rpy="-1.5707963267948966 -0.5235987755983009 1.5707963267948966" />
        <parent link="PP-v4-1" />
        <child link="PM-v4-4" />
        <axis xyz="-4.547206877597018e-17 0.573576 0.819152" />
        <limit lower="-1.919862" upper="0.0" effort="1000000" velocity="1000000" />
    </joint>
    <joint name="PM-v4-4_旋转-25" type="revolute">
        <origin xyz="-0.0014999999999999992 0.022791840000000008 -0.017790180000000006" rpy="-1.665334536936862e-16 -1.1102230246282383e-16 2.0194839173657902e-28" />
        <parent link="PM-v4-4" />
        <child link="PD-v5-4" />
        <axis xyz="4.547207233117271e-17 0.5735759999999999 0.8191520000000001" />
        <limit lower="-1.22173" upper="0.0" effort="1000000" velocity="1000000" />
    </joint>
    <joint name="PD-v5_刚性-26" type="fixed">
        <origin xyz="0.007591700000016362 0.02014129999999998 0.019673260000000026" rpy="1.3877787807814466e-17 1.570796326794065 0" />
        <parent link="PD-v5" />
        <child link="point-v1-4" />
    </joint>
    <joint name="PD-v5-2_刚性-27" type="fixed">
        <origin xyz="-0.005000000000000058 0.028728710000000036 -6.877000000000245e-05" rpy="-1.0096957363644837e-28 1.570796326794065 0" />
        <parent link="PD-v5-2" />
        <child link="point-v1-3" />
    </joint>
    <joint name="PD-v5-1_刚性-28" type="fixed">
        <origin xyz="-0.00500000000000624 0.027732000000000027 -0.007501959999999996" rpy="1.0916253762865456e-43 1.570796326794065 0" />
        <parent link="PD-v5-1" />
        <child link="point-v1" />
    </joint>
    <joint name="PD-v5-3_刚性-29" type="fixed">
        <origin xyz="-0.005000000000011994 0.024845400000000028 -0.014423909999999993" rpy="5.048709793414476e-29 1.570796326794065 0" />
        <parent link="PD-v5-3" />
        <child link="point-v1-1" />
    </joint>
    <joint name="PD-v5-4_刚性-30" type="fixed">
        <origin xyz="-0.00500000000001834 0.018413769999999944 -0.022051670000000002" rpy="-9.244463745722355e-33 1.570796326794065 0" />
        <parent link="PD-v5-4" />
        <child link="point-v1-2" />
    </joint>
</robot>